Workbook

Sheet Sheet5
A3: Row Labels | B3: Count of Emp ID | D3: Count of Emp ID
A4: Female | B4: 54 | D4: 100 | H4: Row Labels | I4: Sum of Salary
A5: Male | B5: 46 | H5: Engineering | I5: 1561000
A6: Grand Total | B6: 100 | H6: Finance | I6: 1428500
H7: HR | I7: 1383000
H8: Marketing | I8: 1712000
B9: Row Labels | C9: Count of Emp ID | H9: Sales | I9: 962000
B10: Account Manager | C10: 3 | H10: Grand Total | I10: 7046500
B11: Accountant | C11: 7
B12: Content Writer | C12: 4
B13: Developer | C13: 5 | F13: Row Labels | G13: Count of Emp ID
B14: Finance Manager | C14: 5 | F14: 2015 | G14: 16
B15: Financial Analyst | C15: 7 | F15: 2016 | G15: 8
B16: HR Executive | C16: 9 | F16: 2017 | G16: 8
B17: HR Manager | C17: 9 | F17: 2018 | G17: 9
B18: Marketing Analyst | C18: 14 | F18: 2019 | G18: 12
B19: QA Engineer | C19: 4 | F19: 2020 | G19: 13
B20: Recruiter | C20: 6 | F20: 2021 | G20: 7
B21: Sales Executive | C21: 4 | F21: 2022 | G21: 8
B22: Sales Lead | C22: 8 | F22: 2023 | G22: 9
B23: Senior Developer | C23: 5 | F23: 2024 | G23: 10
B24: SEO Specialist | C24: 8 | F24: Grand Total | G24: 100
B25: Tech Lead | C25: 2
B26: Grand Total | C26: 100
A30: Row Labels | B30: Count of Emp ID | D30: Row Labels | E30: Average of Salary | G30: Row Labels | H30: Count of Emp ID
A31: Excellent | B31: 19 | D31: Engineering | E31: 97562.5 | G31: Bangalore | H31: 16
A32: Good | B32: 40 | D32: Finance | E32: 75184.211 | G32: Chennai | H32: 17
A33: Average | B33: 29 | D33: HR | E33: 57625 | G33: Delhi | H33: 19
A34: Poor | B34: 12 | D34: Marketing | E34: 65846.154 | G34: Hyderabad | H34: 16
A35: Grand Total | B35: 100 | D35: Sales | E35: 64133.333 | G35: Mumbai | H35: 19
D36: Grand Total | E36: 70465 | G36: Pune | H36: 13
G37: Grand Total | H37: 100
D42: Row Labels | E42: Sum of Salary
D43: Engineering | E43: 1561000
D44: Finance | E44: 1428500
D45: HR | E45: 1383000
D46: Marketing | E46: 1712000
D47: Sales | E47: 962000
D48: Grand Total | E48: 7046500

Sheet Employees
A1: Emp ID | B1: First Name | C1: Last Name | D1: Gender | E1: Department | F1: Job Title | G1: Hire Date | H1: Salary | I1: Bonus | J1: Performance Rating | K1: City | L1: Status | M1: Phone | N1: full name | O1: salary and bonus | P1: EXPERIENCE | Q1: RATING
A2: E1001 | B2: Ananya | C2: Khan | D2: Female | E2: HR | F2: HR Executive | G2: 42202 | H2: 77500 | I2: 0 | J2: Average | K2: Bangalore | L2: Active | M2: 9644854973 | N2: =B2&" "&C2 -> Ananya Khan | O2: =H2+I2 -> 77500 | P2: =DATEDIF(G2,TODAY(),"Y") -> 11 | Q2: =IF(H2>=100000,"A",IF(H2>=60000,"B","C")) -> B
A3: E1002 | B3: Divya | C3: Mehta | D3: Female | E3: Engineering | F3: Developer | G3: 42376 | H3: 91500 | I3: 9200 | J3: Good | K3: Chennai | L3: Active | M3: no phone | N3: =B3&" "&C3 -> Divya Mehta | O3: =H3+I3 -> 100700 | P3: =DATEDIF(G3,TODAY(),"Y") -> 10 | Q3: =IF(H3>=100000,"A",IF(H3>=60000,"B","C")) -> B
A4: E1003 | B4: Priya | C4: Das | D4: Female | E4: Sales | F4: Sales Lead | G4: 44285 | H4: 43000 | I4: 0 | J4: Good | K4: Hyderabad | L4: Active | M4: no phone | N4: =B4&" "&C4 -> Priya Das | O4: =H4+I4 -> 43000 | P4: =DATEDIF(G4,TODAY(),"Y") -> 5 | Q4: =IF(H4>=100000,"A",IF(H4>=60000,"B","C")) -> C | S4: TOTAL EMPLOYEE
A5: E1004 | B5: Rahul | C5: Patel | D5: Male | E5: Finance | F5: Finance Manager | G5: 44621 | H5: 82500 | I5: 0 | J5: Good | K5: Mumbai | L5: Active | M5: no phone | N5: =B5&" "&C5 -> Rahul Patel | O5: =H5+I5 -> 82500 | P5: =DATEDIF(G5,TODAY(),"Y") -> 4 | Q5: =IF(H5>=100000,"A",IF(H5>=60000,"B","C")) -> B | S5: =COUNTA(Employees!A2:A101) -> 100
A6: E1005 | B6: Emma | C6: Nair | D6: Female | E6: Finance | F6: Finance Manager | G6: 45188 | H6: 73000 | I6: 0 | J6: Good | K6: Mumbai | L6: Resigned | M6: 9366746013 | N6: =B6&" "&C6 -> Emma Nair | O6: =H6+I6 -> 73000 | P6: =DATEDIF(G6,TODAY(),"Y") -> 3 | Q6: =IF(H6>=100000,"A",IF(H6>=60000,"B","C")) -> B | S6: ACTIVE
A7: E1006 | B7: Nikhil | C7: Davis | D7: Male | E7: Marketing | F7: Marketing Analyst | G7: 44032 | H7: 74500 | I7: 0 | J7: Average | K7: Delhi | L7: Active | M7: 9226772164 | N7: =B7&" "&C7 -> Nikhil Davis | O7: =H7+I7 -> 74500 | P7: =DATEDIF(G7,TODAY(),"Y") -> 6 | Q7: =IF(H7>=100000,"A",IF(H7>=60000,"B","C")) -> B | S7: =COUNTIF(L2:L101,"ACTIVE") -> 90
A8: E1007 | B8: Lucas | C8: Smith | D8: Male | E8: HR | F8: HR Manager | G8: 42165 | H8: 62500 | I8: 0 | J8: Average | K8: Delhi | L8: Active | M8: 9436883827 | N8: =B8&" "&C8 -> Lucas Smith | O8: =H8+I8 -> 62500 | P8: =DATEDIF(G8,TODAY(),"Y") -> 11 | Q8: =IF(H8>=100000,"A",IF(H8>=60000,"B","C")) -> B | S8: RESIGNED
A9: E1008 | B9: Riya | C9: Das | D9: Female | E9: HR | F9: HR Manager | G9: 45445 | H9: 39500 | I9: 0 | J9: Poor | K9: Chennai | L9: Active | M9: 9165143298 | N9: =B9&" "&C9 -> Riya Das | O9: =H9+I9 -> 39500 | P9: =DATEDIF(G9,TODAY(),"Y") -> 2 | Q9: =IF(H9>=100000,"A",IF(H9>=60000,"B","C")) -> C | S9: =COUNTIF(L2:L101,"RESIGNED") -> 9
A10: E1009 | B10: Kavya | C10: Patel | D10: Female | E10: HR | F10: HR Executive | G10: 43426 | H10: 79000 | I10: ) | J10: Poor | K10: Delhi | L10: Active | M10: 9630098818 | N10: =B10&" "&C10 -> Kavya Patel | O10: =H10+I10 -> #VALUE! | P10: =DATEDIF(G10,TODAY(),"Y") -> 7 | Q10: =IF(H10>=100000,"A",IF(H10>=60000,"B","C")) -> B | S10: ON LEAVE
A11: E1010 | B11: Liam | C11: Davis | D11: Male | E11: Sales | F11: Sales Lead | G11: 43606 | H11: 66000 | I11: 3300 | J11: Excellent | K11: Delhi | L11: Active | M11: 9247023327 | N11: =B11&" "&C11 -> Liam Davis | O11: =H11+I11 -> 69300 | P11: =DATEDIF(G11,TODAY(),"Y") -> 7 | Q11: =IF(H11>=100000,"A",IF(H11>=60000,"B","C")) -> B | S11: =COUNTIF(L2:L101,"ON LEAVE") -> 1
A12: E1011 | B12: Pooja | C12: Nair | D12: Female | E12: HR | F12: Recruiter | G12: 42623 | H12: 50000 | I12: 0 | J12: Good | K12: Delhi | L12: Active | M12: 9620724767 | N12: =B12&" "&C12 -> Pooja Nair | O12: =H12+I12 -> 50000 | P12: =DATEDIF(G12,TODAY(),"Y") -> 10 | Q12: =IF(H12>=100000,"A",IF(H12>=60000,"B","C")) -> C | S12: ATTRITION
A13: E1012 | B13: Vikram | C13: Patel | D13: Male | E13: HR | F13: Recruiter | G13: 43517 | H13: 70000 | I13: 7000 | J13: Good | K13: Hyderabad | L13: On Leave | M13: 9653504709 | N13: =B13&" "&C13 -> Vikram Patel | O13: =H13+I13 -> 77000 | P13: =DATEDIF(G13,TODAY(),"Y") -> 7 | Q13: =IF(H13>=100000,"A",IF(H13>=60000,"B","C")) -> B | S13: =$S$9/$S$5 -> 0.09
A14: E1013 | B14: Divya | C14: Khan | D14: Female | E14: HR | F14: Recruiter | G14: 42429 | H14: 61000 | I14: 3000 | J14: Average | K14: Mumbai | L14: Active | M14: no phone | N14: =B14&" "&C14 -> Divya Khan | O14: =H14+I14 -> 64000 | P14: =DATEDIF(G14,TODAY(),"Y") -> 10 | Q14: =IF(H14>=100000,"A",IF(H14>=60000,"B","C")) -> B | S14: AVG SAL
A15: E1014 | B15: Imran | C15: Sharma | D15: Male | E15: Finance | F15: Accountant | G15: 42424 | H15: 48500 | I15: 0 | J15: Good | K15: Mumbai | L15: Active | M15: 9758995368 | N15: =B15&" "&C15 -> Imran Sharma | O15: =H15+I15 -> 48500 | P15: =DATEDIF(G15,TODAY(),"Y") -> 10 | Q15: =IF(H15>=100000,"A",IF(H15>=60000,"B","C")) -> C | S15: =AVERAGE($H$3:$H$101) -> 70393.939
A16: E1015 | B16: Ananya | C16: Taylor | D16: Female | E16: Marketing | F16: Content Writer | G16: 44471 | H16: 63000 | I16: 0 | J16: Good | K16: Delhi | L16: Active | M16: 9600352373 | N16: =B16&" "&C16 -> Ananya Taylor | O16: =H16+I16 -> 63000 | P16: =DATEDIF(G16,TODAY(),"Y") -> 5 | Q16: =IF(H16>=100000,"A",IF(H16>=60000,"B","C")) -> B | S16: TOTAL PAYROLL
A17: E1016 | B17: Vikram | C17: Johnson | D17: Male | E17: Engineering | F17: Senior Developer | G17: 45037 | H17: 105000 | I17: 0 | J17: Good | K17: Hyderabad | L17: Active | M17: 9320347933 | N17: =B17&" "&C17 -> Vikram Johnson | O17: =H17+I17 -> 105000 | P17: =DATEDIF(G17,TODAY(),"Y") -> 3 | Q17: =IF(H17>=100000,"A",IF(H17>=60000,"B","C")) -> A | S17: =SUM($H$13:$H$101) -> 6307500
A18: E1017 | B18: Noah | C18: Johnson | D18: Male | E18: Finance | F18: Accountant | G18: 44638 | H18: 64500 | I18: 0 | J18: Average | K18: Chennai | L18: Active | M18: 9279360017 | N18: =B18&" "&C18 -> Noah Johnson | O18: =H18+I18 -> 64500 | P18: =DATEDIF(G18,TODAY(),"Y") -> 4 | Q18: =IF(H18>=100000,"A",IF(H18>=60000,"B","C")) -> B | S18: TOTAL BONUS
A19: E1018 | B19: Emma | C19: Khan | D19: Female | E19: Sales | F19: Sales Lead | G19: 45328 | H19: 80000 | I19: 0 | J19: Average | K19: Pune | L19: Active | M19: 9343459673 | N19: =B19&" "&C19 -> Emma Khan | O19: =H19+I19 -> 80000 | P19: =DATEDIF(G19,TODAY(),"Y") -> 2 | Q19: =IF(H19>=100000,"A",IF(H19>=60000,"B","C")) -> B | S19: =SUM($I$2:$I$101) -> 184700
A20: E1019 | B20: Olivia | C20: Wilson | D20: Female | E20: Engineering | F20: QA Engineer | G20: 45241 | H20: 63500 | I20: 0 | J20: Good | K20: Delhi | L20: Active | M20: 9469668829 | N20: =B20&" "&C20 -> Olivia Wilson | O20: =H20+I20 -> 63500 | P20: =DATEDIF(G20,TODAY(),"Y") -> 2 | Q20: =IF(H20>=100000,"A",IF(H20>=60000,"B","C")) -> B | S20: Average age of service
A21: E1020 | B21: Rohan | C21: Sharma | D21: Male | E21: Engineering | F21: Tech Lead | G21: 43930 | H21: 89500 | I21: 0 | J21: Good | K21: Hyderabad | L21: Active | M21: 9755263987 | N21: =B21&" "&C21 -> Rohan Sharma | O21: =H21+I21 -> 89500 | P21: =DATEDIF(G21,TODAY(),"Y") -> 6 | Q21: =IF(H21>=100000,"A",IF(H21>=60000,"B","C")) -> B | S21: =AVERAGE($P$12:$P$101) -> 6.6111111
A22: E1021 | B22: Sophia | C22: Davis | D22: Female | E22: Engineering | F22: QA Engineer | G22: 42496 | H22: 146500 | I22: 7300 | J22: Average | K22: Bangalore | L22: Active | M22: 9291686239 | N22: =B22&" "&C22 -> Sophia Davis | O22: =H22+I22 -> 153800 | P22: =DATEDIF(G22,TODAY(),"Y") -> 10 | Q22: =IF(H22>=100000,"A",IF(H22>=60000,"B","C")) -> A
A23: E1022 | B23: Meera | C23: Reddy | D23: Female | E23: HR | F23: HR Manager | G23: 44973 | H23: 40500 | I23: 0 | J23: Good | K23: Chennai | L23: Active | M23: 9599669927 | N23: =B23&" "&C23 -> Meera Reddy | O23: =H23+I23 -> 40500 | P23: =DATEDIF(G23,TODAY(),"Y") -> 3 | Q23: =IF(H23>=100000,"A",IF(H23>=60000,"B","C")) -> C
A24: E1023 | B24: Emma | C24: Gupta | D24: Female | E24: Marketing | F24: SEO Specialist | G24: 44252 | H24: 50000 | I24: 5000 | J24: Excellent | K24: Hyderabad | L24: Active | M24: 9797582865 | N24: =B24&" "&C24 -> Emma Gupta | O24: =H24+I24 -> 55000 | P24: =DATEDIF(G24,TODAY(),"Y") -> 5 | Q24: =IF(H24>=100000,"A",IF(H24>=60000,"B","C")) -> C
A25: E1024 | B25: Karan | C25: Smith | D25: Male | E25: Sales | F25: Account Manager | G25: 45584 | H25: 94000 | I25: 0 | J25: Excellent | K25: Chennai | L25: Active | M25: 9919994920 | N25: =B25&" "&C25 -> Karan Smith | O25: =H25+I25 -> 94000 | P25: =DATEDIF(G25,TODAY(),"Y") -> 2 | Q25: =IF(H25>=100000,"A",IF(H25>=60000,"B","C")) -> B
A26: E1025 | B26: Ava | C26: Davis | D26: Female | E26: Sales | F26: Sales Lead | G26: 45035 | H26: 44000 | I26: 0 | J26: Average | K26: Mumbai | L26: Active | M26: 9654867725 | N26: =B26&" "&C26 -> Ava Davis | O26: =H26+I26 -> 44000 | P26: =DATEDIF(G26,TODAY(),"Y") -> 3 | Q26: =IF(H26>=100000,"A",IF(H26>=60000,"B","C")) -> C
A27: E1026 | B27: Sanjay | C27: Nair | D27: Male | E27: Finance | F27: Accountant | G27: 45580 | H27: 46000 | I27: 2300 | J27: Average | K27: Pune | L27: Active | M27: 9260849193 | N27: =B27&" "&C27 -> Sanjay Nair | O27: =H27+I27 -> 48300 | P27: =DATEDIF(G27,TODAY(),"Y") -> 2 | Q27: =IF(H27>=100000,"A",IF(H27>=60000,"B","C")) -> C
A28: E1027 | B28: Sanjay | C28: Patel | D28: Male | E28: Engineering | F28: Senior Developer | G28: 44799 | H28: 102500 | I28: 10200 | J28: Good | K28: Mumbai | L28: Active | M28: 9701613399 | N28: =B28&" "&C28 -> Sanjay Patel | O28: =H28+I28 -> 112700 | P28: =DATEDIF(G28,TODAY(),"Y") -> 4 | Q28: =IF(H28>=100000,"A",IF(H28>=60000,"B","C")) -> A
A29: E1028 | B29: Priya | C29: Smith | D29: Female | E29: Engineering | F29: Senior Developer | G29: 43857 | H29: 126500 | I29: 12600 | J29: Excellent | K29: Hyderabad | L29: Resigned | M29: no phone | N29: =B29&" "&C29 -> Priya Smith | O29: =H29+I29 -> 139100 | P29: =DATEDIF(G29,TODAY(),"Y") -> 6 | Q29: =IF(H29>=100000,"A",IF(H29>=60000,"B","C")) -> A
A30: E1029 | B30: Meera | C30: Khan | D30: Female | E30: Finance | F30: Financial Analyst | G30: 45311 | H30: 80000 | I30: 4000 | J30: Good | K30: Mumbai | L30: Active | M30: 9378735098 | N30: =B30&" "&C30 -> Meera Khan | O30: =H30+I30 -> 84000 | P30: =DATEDIF(G30,TODAY(),"Y") -> 2 | Q30: =IF(H30>=100000,"A",IF(H30>=60000,"B","C")) -> B
A31: E1030 | B31: Sneha | C31: Gupta | D31: Female | E31: HR | F31: HR Executive | G31: 43299 | H31: 64000 | I31: 0 | J31: Average | K31: Hyderabad | L31: Active | M31: 9425107627 | N31: =B31&" "&C31 -> Sneha Gupta | O31: =H31+I31 -> 64000 | P31: =DATEDIF(G31,TODAY(),"Y") -> 8 | Q31: =IF(H31>=100000,"A",IF(H31>=60000,"B","C")) -> B
A32: E1031 | B32: Ananya | C32: Mehta | D32: Female | E32: Marketing | F32: Marketing Analyst | G32: 43920 | H32: 49000 | I32: 0 | J32: Average | K32: Hyderabad | L32: Active | M32: 9274799977 | N32: =B32&" "&C32 -> Ananya Mehta | O32: =H32+I32 -> 49000 | P32: =DATEDIF(G32,TODAY(),"Y") -> 6 | Q32: =IF(H32>=100000,"A",IF(H32>=60000,"B","C")) -> C
A33: E1032 | B33: Isha | C33: Wilson | D33: Female | E33: HR | F33: Recruiter | G33: 43730 | H33: 57000 | I33: 0 | J33: Good | K33: Hyderabad | L33: Active | M33: 9462902921 | N33: =B33&" "&C33 -> Isha Wilson | O33: =H33+I33 -> 57000 | P33: =DATEDIF(G33,TODAY(),"Y") -> 7 | Q33: =IF(H33>=100000,"A",IF(H33>=60000,"B","C")) -> C
... A101: E1100 | B101: Sneha | C101: Singh | D101: Female | E101: HR | F101: HR Executive | G101: 44094 | H101: 68000 | I101: 0 | J101: Excellent | K101: Chennai | L101: Active | M101: 9436860564 | N101: =B101&" "&C101 -> Sneha Singh | O101: =H101+I101 -> 68000 | P101: =DATEDIF(G101,TODAY(),"Y") -> 6 | Q101: =IF(H101>=100000,"A",IF(H101>=60000,"B","C")) -> B
N102: =B102&" "&C102

Sheet Hr Dashboard

Sheet Data_Clean
A1: Emp ID | B1: First Name | C1: Last Name | D1: Gender | E1: Department | F1: Job Title | G1: Hire Date | H1: Salary | I1: Bonus | J1: Performance Rating | K1: City | L1: Status | M1: Phone | N1: Full Name | O1: Total Pay | P1: Years of Service | Q1: Grade | R1: Tenure Band | S1: Department Head | T1: Annual Budget | U1: Hire Year
A2: E1001 | B2: Ananya | C2: Khan | D2: Female | E2: HR | F2: HR Executive | G2: 42202 | H2: 77500 | I2: 0 | J2: Average | K2: Bangalore | L2: Active | M2: 9644854973 | N2: =B2&" "&C2 -> Ananya Khan | O2: =SUM(H2:I2) -> 77500 | P2: =DATEDIF(G2,TODAY(),"Y") -> 11 | Q2: =IF(H2>=100000,"A",IF(H2>=60000,"B","C")) -> B | R2: =IF(P2<3,"0-2 yrs",IF(P2<6,"3-5 yrs",IF(P2<9,"6-8 yrs","9+ yrs"))) -> 9+ yrs | S2: =VLOOKUP(E2,Departments!$A$2:$D$6,3,FALSE) -> Rekha Iyer | T2: =VLOOKUP(E2,Departments!$A$2:$D$6,4,FALSE) -> 5000000 | U2: =YEAR(G2) -> 2015
A3: E1002 | B3: Divya | C3: Mehta | D3: Female | E3: Engineering | F3: Developer | G3: 42376 | H3: 91500 | I3: 9200 | J3: Good | K3: Chennai | L3: Active | M3: No Phone | N3: =B3&" "&C3 -> Divya Mehta | O3: =SUM(H3:I3) -> 100700 | P3: =DATEDIF(G3,TODAY(),"Y") -> 10 | Q3: =IF(H3>=100000,"A",IF(H3>=60000,"B","C")) -> B | R3: =IF(P3<3,"0-2 yrs",IF(P3<6,"3-5 yrs",IF(P3<9,"6-8 yrs","9+ yrs"))) -> 9+ yrs | S3: =VLOOKUP(E3,Departments!$A$2:$D$6,3,FALSE) -> Anil Kumar | T3: =VLOOKUP(E3,Departments!$A$2:$D$6,4,FALSE) -> 15000000 | U3: =YEAR(G3) -> 2016 | X3: Row Labels | Y3: Headcount
A4: E1003 | B4: Priya | C4: Das | D4: Female | E4: Sales | F4: Sales Lead | G4: 44285 | H4: 43000 | I4: 0 | J4: Good | K4: Hyderabad | L4: Active | M4: No Phone | N4: =B4&" "&C4 -> Priya Das | O4: =SUM(H4:I4) -> 43000 | P4: =DATEDIF(G4,TODAY(),"Y") -> 5 | Q4: =IF(H4>=100000,"A",IF(H4>=60000,"B","C")) -> C | R4: =IF(P4<3,"0-2 yrs",IF(P4<6,"3-5 yrs",IF(P4<9,"6-8 yrs","9+ yrs"))) -> 3-5 yrs | S4: =VLOOKUP(E4,Departments!$A$2:$D$6,3,FALSE) -> Sunita Rao | T4: =VLOOKUP(E4,Departments!$A$2:$D$6,4,FALSE) -> 9000000 | U4: =YEAR(G4) -> 2021 | X4: Engineering | Y4: 16
A5: E1004 | B5: Rahul | C5: Patel | D5: Male | E5: Finance | F5: Finance Manager | G5: 44621 | H5: 82500 | I5: 0 | J5: Good | K5: Mumbai | L5: Active | M5: No Phone | N5: =B5&" "&C5 -> Rahul Patel | O5: =SUM(H5:I5) -> 82500 | P5: =DATEDIF(G5,TODAY(),"Y") -> 4 | Q5: =IF(H5>=100000,"A",IF(H5>=60000,"B","C")) -> B | R5: =IF(P5<3,"0-2 yrs",IF(P5<6,"3-5 yrs",IF(P5<9,"6-8 yrs","9+ yrs"))) -> 3-5 yrs | S5: =VLOOKUP(E5,Departments!$A$2:$D$6,3,FALSE) -> Suresh Menon | T5: =VLOOKUP(E5,Departments!$A$2:$D$6,4,FALSE) -> 8000000 | U5: =YEAR(G5) -> 2022 | X5: Finance | Y5: 19
A6: E1005 | B6: Emma | C6: Nair | D6: Female | E6: Finance | F6: Finance Manager | G6: 45188 | H6: 73000 | I6: 0 | J6: Good | K6: Mumbai | L6: Resigned | M6: 9366746013 | N6: =B6&" "&C6 -> Emma Nair | O6: =SUM(H6:I6) -> 73000 | P6: =DATEDIF(G6,TODAY(),"Y") -> 3 | Q6: =IF(H6>=100000,"A",IF(H6>=60000,"B","C")) -> B | R6: =IF(P6<3,"0-2 yrs",IF(P6<6,"3-5 yrs",IF(P6<9,"6-8 yrs","9+ yrs"))) -> 3-5 yrs | S6: =VLOOKUP(E6,Departments!$A$2:$D$6,3,FALSE) -> Suresh Menon | T6: =VLOOKUP(E6,Departments!$A$2:$D$6,4,FALSE) -> 8000000 | U6: =YEAR(G6) -> 2023 | X6: HR | Y6: 24
A7: E1006 | B7: Nikhil | C7: Davis | D7: Male | E7: Marketing | F7: Marketing Analyst | G7: 44032 | H7: 74500 | I7: 0 | J7: Average | K7: Delhi | L7: Active | M7: 9226772164 | N7: =B7&" "&C7 -> Nikhil Davis | O7: =SUM(H7:I7) -> 74500 | P7: =DATEDIF(G7,TODAY(),"Y") -> 6 | Q7: =IF(H7>=100000,"A",IF(H7>=60000,"B","C")) -> B | R7: =IF(P7<3,"0-2 yrs",IF(P7<6,"3-5 yrs",IF(P7<9,"6-8 yrs","9+ yrs"))) -> 6-8 yrs | S7: =VLOOKUP(E7,Departments!$A$2:$D$6,3,FALSE) -> David Miller | T7: =VLOOKUP(E7,Departments!$A$2:$D$6,4,FALSE) -> 7000000 | U7: =YEAR(G7) -> 2020 | X7: Marketing | Y7: 26
A8: E1007 | B8: Lucas | C8: Smith | D8: Male | E8: HR | F8: HR Manager | G8: 42165 | H8: 62500 | I8: 0 | J8: Average | K8: Delhi | L8: Active | M8: 9436883827 | N8: =B8&" "&C8 -> Lucas Smith | O8: =SUM(H8:I8) -> 62500 | P8: =DATEDIF(G8,TODAY(),"Y") -> 11 | Q8: =IF(H8>=100000,"A",IF(H8>=60000,"B","C")) -> B | R8: =IF(P8<3,"0-2 yrs",IF(P8<6,"3-5 yrs",IF(P8<9,"6-8 yrs","9+ yrs"))) -> 9+ yrs | S8: =VLOOKUP(E8,Departments!$A$2:$D$6,3,FALSE) -> Rekha Iyer | T8: =VLOOKUP(E8,Departments!$A$2:$D$6,4,FALSE) -> 5000000 | U8: =YEAR(G8) -> 2015 | X8: Sales | Y8: 15
A9: E1008 | B9: Riya | C9: Das | D9: Female | E9: HR | F9: HR Manager | G9: 45445 | H9: 39500 | I9: 0 | J9: Poor | K9: Chennai | L9: Active | M9: 9165143298 | N9: =B9&" "&C9 -> Riya Das | O9: =SUM(H9:I9) -> 39500 | P9: =DATEDIF(G9,TODAY(),"Y") -> 2 | Q9: =IF(H9>=100000,"A",IF(H9>=60000,"B","C")) -> C | R9: =IF(P9<3,"0-2 yrs",IF(P9<6,"3-5 yrs",IF(P9<9,"6-8 yrs","9+ yrs"))) -> 0-2 yrs | S9: =VLOOKUP(E9,Departments!$A$2:$D$6,3,FALSE) -> Rekha Iyer | T9: =VLOOKUP(E9,Departments!$A$2:$D$6,4,FALSE) -> 5000000 | U9: =YEAR(G9) -> 2024
A10: E1009 | B10: Kavya | C10: Patel | D10: Female | E10: HR | F10: HR Executive | G10: 43426 | H10: 79000 | I10: 0 | J10: Poor | K10: Delhi | L10: Active | M10: 9630098818 | N10: =B10&" "&C10 -> Kavya Patel | O10: =SUM(H10:I10) -> 79000 | P10: =DATEDIF(G10,TODAY(),"Y") -> 7 | Q10: =IF(H10>=100000,"A",IF(H10>=60000,"B","C")) -> B | R10: =IF(P10<3,"0-2 yrs",IF(P10<6,"3-5 yrs",IF(P10<9,"6-8 yrs","9+ yrs"))) -> 6-8 yrs | S10: =VLOOKUP(E10,Departments!$A$2:$D$6,3,FALSE) -> Rekha Iyer | T10: =VLOOKUP(E10,Departments!$A$2:$D$6,4,FALSE) -> 5000000 | U10: =YEAR(G10) -> 2018
A11: E1010 | B11: Liam | C11: Davis | D11: Male | E11: Sales | F11: Sales Lead | G11: 43606 | H11: 66000 | I11: 3300 | J11: Excellent | K11: Delhi | L11: Active | M11: 9247023327 | N11: =B11&" "&C11 -> Liam Davis | O11: =SUM(H11:I11) -> 69300 | P11: =DATEDIF(G11,TODAY(),"Y") -> 7 | Q11: =IF(H11>=100000,"A",IF(H11>=60000,"B","C")) -> B | R11: =IF(P11<3,"0-2 yrs",IF(P11<6,"3-5 yrs",IF(P11<9,"6-8 yrs","9+ yrs"))) -> 6-8 yrs | S11: =VLOOKUP(E11,Departments!$A$2:$D$6,3,FALSE) -> Sunita Rao | T11: =VLOOKUP(E11,Departments!$A$2:$D$6,4,FALSE) -> 9000000 | U11: =YEAR(G11) -> 2019
A12: E1011 | B12: Pooja | C12: Nair | D12: Female | E12: HR | F12: Recruiter | G12: 42623 | H12: 50000 | I12: 0 | J12: Good | K12: Delhi | L12: Active | M12: 9620724767 | N12: =B12&" "&C12 -> Pooja Nair | O12: =SUM(H12:I12) -> 50000 | P12: =DATEDIF(G12,TODAY(),"Y") -> 10 | Q12: =IF(H12>=100000,"A",IF(H12>=60000,"B","C")) -> C | R12: =IF(P12<3,"0-2 yrs",IF(P12<6,"3-5 yrs",IF(P12<9,"6-8 yrs","9+ yrs"))) -> 9+ yrs | S12: =VLOOKUP(E12,Departments!$A$2:$D$6,3,FALSE) -> Rekha Iyer | T12: =VLOOKUP(E12,Departments!$A$2:$D$6,4,FALSE) -> 5000000 | U12: =YEAR(G12) -> 2016
A13: E1012 | B13: Vikram | C13: Patel | D13: Male | E13: HR | F13: Recruiter | G13: 43517 | H13: 70000 | I13: 7000 | J13: Good | K13: Hyderabad | L13: On Leave | M13: 9653504709 | N13: =B13&" "&C13 -> Vikram Patel | O13: =SUM(H13:I13) -> 77000 | P13: =DATEDIF(G13,TODAY(),"Y") -> 7 | Q13: =IF(H13>=100000,"A",IF(H13>=60000,"B","C")) -> B | R13: =IF(P13<3,"0-2 yrs",IF(P13<6,"3-5 yrs",IF(P13<9,"6-8 yrs","9+ yrs"))) -> 6-8 yrs | S13: =VLOOKUP(E13,Departments!$A$2:$D$6,3,FALSE) -> Rekha Iyer | T13: =VLOOKUP(E13,Departments!$A$2:$D$6,4,FALSE) -> 5000000 | U13: =YEAR(G13) -> 2019
A14: E1013 | B14: Divya | C14: Khan | D14: Female | E14: HR | F14: Recruiter | G14: 42429 | H14: 61000 | I14: 3000 | J14: Average | K14: Mumbai | L14: Active | M14: No Phone | N14: =B14&" "&C14 -> Divya Khan | O14: =SUM(H14:I14) -> 64000 | P14: =DATEDIF(G14,TODAY(),"Y") -> 10 | Q14: =IF(H14>=100000,"A",IF(H14>=60000,"B","C")) -> B | R14: =IF(P14<3,"0-2 yrs",IF(P14<6,"3-5 yrs",IF(P14<9,"6-8 yrs","9+ yrs"))) -> 9+ yrs | S14: =VLOOKUP(E14,Departments!$A$2:$D$6,3,FALSE) -> Rekha Iyer | T14: =VLOOKUP(E14,Departments!$A$2:$D$6,4,FALSE) -> 5000000 | U14: =YEAR(G14) -> 2016
A15: E1014 | B15: Imran | C15: Sharma | D15: Male | E15: Finance | F15: Accountant | G15: 42424 | H15: 48500 | I15: 0 | J15: Good | K15: Mumbai | L15: Active | M15: 9758995368 | N15: =B15&" "&C15 -> Imran Sharma | O15: =SUM(H15:I15) -> 48500 | P15: =DATEDIF(G15,TODAY(),"Y") -> 10 | Q15: =IF(H15>=100000,"A",IF(H15>=60000,"B","C")) -> C | R15: =IF(P15<3,"0-2 yrs",IF(P15<6,"3-5 yrs",IF(P15<9,"6-8 yrs","9+ yrs"))) -> 9+ yrs | S15: =VLOOKUP(E15,Departments!$A$2:$D$6,3,FALSE) -> Suresh Menon | T15: =VLOOKUP(E15,Departments!$A$2:$D$6,4,FALSE) -> 8000000 | U15: =YEAR(G15) -> 2016
A16: E1015 | B16: Ananya | C16: Taylor | D16: Female | E16: Marketing | F16: Content Writer | G16: 44471 | H16: 63000 | I16: 0 | J16: Good | K16: Delhi | L16: Active | M16: 9600352373 | N16: =B16&" "&C16 -> Ananya Taylor | O16: =SUM(H16:I16) -> 63000 | P16: =DATEDIF(G16,TODAY(),"Y") -> 5 | Q16: =IF(H16>=100000,"A",IF(H16>=60000,"B","C")) -> B | R16: =IF(P16<3,"0-2 yrs",IF(P16<6,"3-5 yrs",IF(P16<9,"6-8 yrs","9+ yrs"))) -> 3-5 yrs | S16: =VLOOKUP(E16,Departments!$A$2:$D$6,3,FALSE) -> David Miller | T16: =VLOOKUP(E16,Departments!$A$2:$D$6,4,FALSE) -> 7000000 | U16: =YEAR(G16) -> 2021
A17: E1016 | B17: Vikram | C17: Johnson | D17: Male | E17: Engineering | F17: Senior Developer | G17: 45037 | H17: 105000 | I17: 0 | J17: Good | K17: Hyderabad | L17: Active | M17: 9320347933 | N17: =B17&" "&C17 -> Vikram Johnson | O17: =SUM(H17:I17) -> 105000 | P17: =DATEDIF(G17,TODAY(),"Y") -> 3 | Q17: =IF(H17>=100000,"A",IF(H17>=60000,"B","C")) -> A | R17: =IF(P17<3,"0-2 yrs",IF(P17<6,"3-5 yrs",IF(P17<9,"6-8 yrs","9+ yrs"))) -> 3-5 yrs | S17: =VLOOKUP(E17,Departments!$A$2:$D$6,3,FALSE) -> Anil Kumar | T17: =VLOOKUP(E17,Departments!$A$2:$D$6,4,FALSE) -> 15000000 | U17: =YEAR(G17) -> 2023
A18: E1017 | B18: Noah | C18: Johnson | D18: Male | E18: Finance | F18: Accountant | G18: 44638 | H18: 64500 | I18: 0 | J18: Average | K18: Chennai | L18: Active | M18: 9279360017 | N18: =B18&" "&C18 -> Noah Johnson | O18: =SUM(H18:I18) -> 64500 | P18: =DATEDIF(G18,TODAY(),"Y") -> 4 | Q18: =IF(H18>=100000,"A",IF(H18>=60000,"B","C")) -> B | R18: =IF(P18<3,"0-2 yrs",IF(P18<6,"3-5 yrs",IF(P18<9,"6-8 yrs","9+ yrs"))) -> 3-5 yrs | S18: =VLOOKUP(E18,Departments!$A$2:$D$6,3,FALSE) -> Suresh Menon | T18: =VLOOKUP(E18,Departments!$A$2:$D$6,4,FALSE) -> 8000000 | U18: =YEAR(G18) -> 2022
A19: E1018 | B19: Emma | C19: Khan | D19: Female | E19: Sales | F19: Sales Lead | G19: 45328 | H19: 80000 | I19: 0 | J19: Average | K19: Pune | L19: Active | M19: 9343459673 | N19: =B19&" "&C19 -> Emma Khan | O19: =SUM(H19:I19) -> 80000 | P19: =DATEDIF(G19,TODAY(),"Y") -> 2 | Q19: =IF(H19>=100000,"A",IF(H19>=60000,"B","C")) -> B | R19: =IF(P19<3,"0-2 yrs",IF(P19<6,"3-5 yrs",IF(P19<9,"6-8 yrs","9+ yrs"))) -> 0-2 yrs | S19: =VLOOKUP(E19,Departments!$A$2:$D$6,3,FALSE) -> Sunita Rao | T19: =VLOOKUP(E19,Departments!$A$2:$D$6,4,FALSE) -> 9000000 | U19: =YEAR(G19) -> 2024
A20: E1019 | B20: Olivia | C20: Wilson | D20: Female | E20: Engineering | F20: QA Engineer | G20: 45241 | H20: 63500 | I20: 0 | J20: Good | K20: Delhi | L20: Active | M20: 9469668829 | N20: =B20&" "&C20 -> Olivia Wilson | O20: =SUM(H20:I20) -> 63500 | P20: =DATEDIF(G20,TODAY(),"Y") -> 2 | Q20: =IF(H20>=100000,"A",IF(H20>=60000,"B","C")) -> B | R20: =IF(P20<3,"0-2 yrs",IF(P20<6,"3-5 yrs",IF(P20<9,"6-8 yrs","9+ yrs"))) -> 0-2 yrs | S20: =VLOOKUP(E20,Departments!$A$2:$D$6,3,FALSE) -> Anil Kumar | T20: =VLOOKUP(E20,Departments!$A$2:$D$6,4,FALSE) -> 15000000 | U20: =YEAR(G20) -> 2023
A21: E1020 | B21: Rohan | C21: Sharma | D21: Male | E21: Engineering | F21: Tech Lead | G21: 43930 | H21: 89500 | I21: 0 | J21: Good | K21: Hyderabad | L21: Active | M21: 9755263987 | N21: =B21&" "&C21 -> Rohan Sharma | O21: =SUM(H21:I21) -> 89500 | P21: =DATEDIF(G21,TODAY(),"Y") -> 6 | Q21: =IF(H21>=100000,"A",IF(H21>=60000,"B","C")) -> B | R21: =IF(P21<3,"0-2 yrs",IF(P21<6,"3-5 yrs",IF(P21<9,"6-8 yrs","9+ yrs"))) -> 6-8 yrs | S21: =VLOOKUP(E21,Departments!$A$2:$D$6,3,FALSE) -> Anil Kumar | T21: =VLOOKUP(E21,Departments!$A$2:$D$6,4,FALSE) -> 15000000 | U21: =YEAR(G21) -> 2020
A22: E1021 | B22: Sophia | C22: Davis | D22: Female | E22: Engineering | F22: QA Engineer | G22: 42496 | H22: 146500 | I22: 7300 | J22: Average | K22: Bangalore | L22: Active | M22: 9291686239 | N22: =B22&" "&C22 -> Sophia Davis | O22: =SUM(H22:I22) -> 153800 | P22: =DATEDIF(G22,TODAY(),"Y") -> 10 | Q22: =IF(H22>=100000,"A",IF(H22>=60000,"B","C")) -> A | R22: =IF(P22<3,"0-2 yrs",IF(P22<6,"3-5 yrs",IF(P22<9,"6-8 yrs","9+ yrs"))) -> 9+ yrs | S22: =VLOOKUP(E22,Departments!$A$2:$D$6,3,FALSE) -> Anil Kumar | T22: =VLOOKUP(E22,Departments!$A$2:$D$6,4,FALSE) -> 15000000 | U22: =YEAR(G22) -> 2016
A23: E1022 | B23: Meera | C23: Reddy | D23: Female | E23: HR | F23: HR Manager | G23: 44973 | H23: 40500 | I23: 0 | J23: Good | K23: Chennai | L23: Active | M23: 9599669927 | N23: =B23&" "&C23 -> Meera Reddy | O23: =SUM(H23:I23) -> 40500 | P23: =DATEDIF(G23,TODAY(),"Y") -> 3 | Q23: =IF(H23>=100000,"A",IF(H23>=60000,"B","C")) -> C | R23: =IF(P23<3,"0-2 yrs",IF(P23<6,"3-5 yrs",IF(P23<9,"6-8 yrs","9+ yrs"))) -> 3-5 yrs | S23: =VLOOKUP(E23,Departments!$A$2:$D$6,3,FALSE) -> Rekha Iyer | T23: =VLOOKUP(E23,Departments!$A$2:$D$6,4,FALSE) -> 5000000 | U23: =YEAR(G23) -> 2023
A24: E1023 | B24: Emma | C24: Gupta | D24: Female | E24: Marketing | F24: SEO Specialist | G24: 44252 | H24: 50000 | I24: 5000 | J24: Excellent | K24: Hyderabad | L24: Active | M24: 9797582865 | N24: =B24&" "&C24 -> Emma Gupta | O24: =SUM(H24:I24) -> 55000 | P24: =DATEDIF(G24,TODAY(),"Y") -> 5 | Q24: =IF(H24>=100000,"A",IF(H24>=60000,"B","C")) -> C | R24: =IF(P24<3,"0-2 yrs",IF(P24<6,"3-5 yrs",IF(P24<9,"6-8 yrs","9+ yrs"))) -> 3-5 yrs | S24: =VLOOKUP(E24,Departments!$A$2:$D$6,3,FALSE) -> David Miller | T24: =VLOOKUP(E24,Departments!$A$2:$D$6,4,FALSE) -> 7000000 | U24: =YEAR(G24) -> 2021
A25: E1024 | B25: Karan | C25: Smith | D25: Male | E25: Sales | F25: Account Manager | G25: 45584 | H25: 94000 | I25: 0 | J25: Excellent | K25: Chennai | L25: Active | M25: 9919994920 | N25: =B25&" "&C25 -> Karan Smith | O25: =SUM(H25:I25) -> 94000 | P25: =DATEDIF(G25,TODAY(),"Y") -> 2 | Q25: =IF(H25>=100000,"A",IF(H25>=60000,"B","C")) -> B | R25: =IF(P25<3,"0-2 yrs",IF(P25<6,"3-5 yrs",IF(P25<9,"6-8 yrs","9+ yrs"))) -> 0-2 yrs | S25: =VLOOKUP(E25,Departments!$A$2:$D$6,3,FALSE) -> Sunita Rao | T25: =VLOOKUP(E25,Departments!$A$2:$D$6,4,FALSE) -> 9000000 | U25: =YEAR(G25) -> 2024
A26: E1025 | B26: Ava | C26: Davis | D26: Female | E26: Sales | F26: Sales Lead | G26: 45035 | H26: 44000 | I26: 0 | J26: Average | K26: Mumbai | L26: Active | M26: 9654867725 | N26: =B26&" "&C26 -> Ava Davis | O26: =SUM(H26:I26) -> 44000 | P26: =DATEDIF(G26,TODAY(),"Y") -> 3 | Q26: =IF(H26>=100000,"A",IF(H26>=60000,"B","C")) -> C | R26: =IF(P26<3,"0-2 yrs",IF(P26<6,"3-5 yrs",IF(P26<9,"6-8 yrs","9+ yrs"))) -> 3-5 yrs | S26: =VLOOKUP(E26,Departments!$A$2:$D$6,3,FALSE) -> Sunita Rao | T26: =VLOOKUP(E26,Departments!$A$2:$D$6,4,FALSE) -> 9000000 | U26: =YEAR(G26) -> 2023
... A28: E1027 | B28: Sanjay | C28: Patel | D28: Male | E28: Engineering | F28: Senior Developer | G28: 44799 | H28: 102500 | I28: 10200 | J28: Good | K28: Mumbai | L28: Active | M28: 9701613399 | N28: =B28&" "&C28 -> Sanjay Patel | O28: =SUM(H28:I28) -> 112700 | P28: =DATEDIF(G28,TODAY(),"Y") -> 4 | Q28: =IF(H28>=100000,"A",IF(H28>=60000,"B","C")) -> A | R28: =IF(P28<3,"0-2 yrs",IF(P28<6,"3-5 yrs",IF(P28<9,"6-8 yrs","9+ yrs"))) -> 3-5 yrs | S28: =VLOOKUP(E28,Departments!$A$2:$D$6,3,FALSE) -> Anil Kumar | T28: =VLOOKUP(E28,Departments!$A$2:$D$6,4,FALSE) -> 15000000 | U28: =YEAR(G28) -> 2022
A29: E1028 | B29: Priya | C29: Smith | D29: Female | E29: Engineering | F29: Senior Developer | G29: 43857 | H29: 126500 | I29: 12600 | J29: Excellent | K29: Hyderabad | L29: Resigned | M29: No Phone | N29: =B29&" "&C29 -> Priya Smith | O29: =SUM(H29:I29) -> 139100 | P29: =DATEDIF(G29,TODAY(),"Y") -> 6 | Q29: =IF(H29>=100000,"A",IF(H29>=60000,"B","C")) -> A | R29: =IF(P29<3,"0-2 yrs",IF(P29<6,"3-5 yrs",IF(P29<9,"6-8 yrs","9+ yrs"))) -> 6-8 yrs | S29: =VLOOKUP(E29,Departments!$A$2:$D$6,3,FALSE) -> Anil Kumar | T29: =VLOOKUP(E29,Departments!$A$2:$D$6,4,FALSE) -> 15000000 | U29: =YEAR(G29) -> 2020
A30: E1029 | B30: Meera | C30: Khan | D30: Female | E30: Finance | F30: Financial Analyst | G30: 45311 | H30: 80000 | I30: 4000 | J30: Good | K30: Mumbai | L30: Active | M30: 9378735098 | N30: =B30&" "&C30 -> Meera Khan | O30: =SUM(H30:I30) -> 84000 | P30: =DATEDIF(G30,TODAY(),"Y") -> 2 | Q30: =IF(H30>=100000,"A",IF(H30>=60000,"B","C")) -> B | R30: =IF(P30<3,"0-2 yrs",IF(P30<6,"3-5 yrs",IF(P30<9,"6-8 yrs","9+ yrs"))) -> 0-2 yrs | S30: =VLOOKUP(E30,Departments!$A$2:$D$6,3,FALSE) -> Suresh Menon | T30: =VLOOKUP(E30,Departments!$A$2:$D$6,4,FALSE) -> 8000000 | U30: =YEAR(G30) -> 2024
A31: E1030 | B31: Sneha | C31: Gupta | D31: Female | E31: HR | F31: HR Executive | G31: 43299 | H31: 64000 | I31: 0 | J31: Average | K31: Hyderabad | L31: Active | M31: 9425107627 | N31: =B31&" "&C31 -> Sneha Gupta | O31: =SUM(H31:I31) -> 64000 | P31: =DATEDIF(G31,TODAY(),"Y") -> 8 | Q31: =IF(H31>=100000,"A",IF(H31>=60000,"B","C")) -> B | R31: =IF(P31<3,"0-2 yrs",IF(P31<6,"3-5 yrs",IF(P31<9,"6-8 yrs","9+ yrs"))) -> 6-8 yrs | S31: =VLOOKUP(E31,Departments!$A$2:$D$6,3,FALSE) -> Rekha Iyer | T31: =VLOOKUP(E31,Departments!$A$2:$D$6,4,FALSE) -> 5000000 | U31: =YEAR(G31) -> 2018
A32: E1031 | B32: Ananya | C32: Mehta | D32: Female | E32: Marketing | F32: Marketing Analyst | G32: 43920 | H32: 49000 | I32: 0 | J32: Average | K32: Hyderabad | L32: Active | M32: 9274799977 | N32: =B32&" "&C32 -> Ananya Mehta | O32: =SUM(H32:I32) -> 49000 | P32: =DATEDIF(G32,TODAY(),"Y") -> 6 | Q32: =IF(H32>=100000,"A",IF(H32>=60000,"B","C")) -> C | R32: =IF(P32<3,"0-2 yrs",IF(P32<6,"3-5 yrs",IF(P32<9,"6-8 yrs","9+ yrs"))) -> 6-8 yrs | S32: =VLOOKUP(E32,Departments!$A$2:$D$6,3,FALSE) -> David Miller | T32: =VLOOKUP(E32,Departments!$A$2:$D$6,4,FALSE) -> 7000000 | U32: =YEAR(G32) -> 2020
A33: E1032 | B33: Isha | C33: Wilson | D33: Female | E33: HR | F33: Recruiter | G33: 43730 | H33: 57000 | I33: 0 | J33: Good | K33: Hyderabad | L33: Active | M33: 9462902921 | N33: =B33&" "&C33 -> Isha Wilson | O33: =SUM(H33:I33) -> 57000 | P33: =DATEDIF(G33,TODAY(),"Y") -> 7 | Q33: =IF(H33>=100000,"A",IF(H33>=60000,"B","C")) -> C | R33: =IF(P33<3,"0-2 yrs",IF(P33<6,"3-5 yrs",IF(P33<9,"6-8 yrs","9+ yrs"))) -> 6-8 yrs | S33: =VLOOKUP(E33,Departments!$A$2:$D$6,3,FALSE) -> Rekha Iyer | T33: =VLOOKUP(E33,Departments!$A$2:$D$6,4,FALSE) -> 5000000 | U33: =YEAR(G33) -> 2019
A34: E1033 | B34: Karan | C34: Mehta | D34: Male | E34: Marketing | F34: Marketing Analyst | G34: 44560 | H34: 74000 | I34: 0 | J34: Good | K34: Bangalore | L34: Active | M34: 9946498388 | N34: =B34&" "&C34 -> Karan Mehta | O34: =SUM(H34:I34) -> 74000 | P34: =DATEDIF(G34,TODAY(),"Y") -> 4 | Q34: =IF(H34>=100000,"A",IF(H34>=60000,"B","C")) -> B | R34: =IF(P34<3,"0-2 yrs",IF(P34<6,"3-5 yrs",IF(P34<9,"6-8 yrs","9+ yrs"))) -> 3-5 yrs | S34: =VLOOKUP(E34,Departments!$A$2:$D$6,3,FALSE) -> David Miller | T34: =VLOOKUP(E34,Departments!$A$2:$D$6,4,FALSE) -> 7000000 | U34: =YEAR(G34) -> 2021
A35: E1034 | B35: Kavya | C35: Brown | D35: Female | E35: Engineering | F35: Senior Developer | G35: 43112 | H35: 84000 | I35: 0 | J35: Average | K35: Chennai | L35: Active | M35: 9377679317 | N35: =B35&" "&C35 -> Kavya Brown | O35: =SUM(H35:I35) -> 84000 | P35: =DATEDIF(G35,TODAY(),"Y") -> 8 | Q35: =IF(H35>=100000,"A",IF(H35>=60000,"B","C")) -> B | R35: =IF(P35<3,"0-2 yrs",IF(P35<6,"3-5 yrs",IF(P35<9,"6-8 yrs","9+ yrs"))) -> 6-8 yrs | S35: =VLOOKUP(E35,Departments!$A$2:$D$6,3,FALSE) -> Anil Kumar | T35: =VLOOKUP(E35,Departments!$A$2:$D$6,4,FALSE) -> 15000000 | U35: =YEAR(G35) -> 2018
A36: E1035 | B36: Olivia | C36: Sharma | D36: Female | E36: Marketing | F36: SEO Specialist | G36: 43148 | H36: 46000 | I36: 0 | J36: Average | K36: Bangalore | L36: Active | M36: 9388754324 | N36: =B36&" "&C36 -> Olivia Sharma | O36: =SUM(H36:I36) -> 46000 | P36: =DATEDIF(G36,TODAY(),"Y") -> 8 | Q36: =IF(H36>=100000,"A",IF(H36>=60000,"B","C")) -> C | R36: =IF(P36<3,"0-2 yrs",IF(P36<6,"3-5 yrs",IF(P36<9,"6-8 yrs","9+ yrs"))) -> 6-8 yrs | S36: =VLOOKUP(E36,Departments!$A$2:$D$6,3,FALSE) -> David Miller | T36: =VLOOKUP(E36,Departments!$A$2:$D$6,4,FALSE) -> 7000000 | U36: =YEAR(G36) -> 2018
A37: E1036 | B37: Sneha | C37: Davis | D37: Female | E37: Finance | F37: Financial Analyst | G37: 42915 | H37: 101000 | I37: 0 | J37: Good | K37: Chennai | L37: Active | M37: No Phone | N37: =B37&" "&C37 -> Sneha Davis | O37: =SUM(H37:I37) -> 101000 | P37: =DATEDIF(G37,TODAY(),"Y") -> 9 | Q37: =IF(H37>=100000,"A",IF(H37>=60000,"B","C")) -> A | R37: =IF(P37<3,"0-2 yrs",IF(P37<6,"3-5 yrs",IF(P37<9,"6-8 yrs","9+ yrs"))) -> 9+ yrs | S37: =VLOOKUP(E37,Departments!$A$2:$D$6,3,FALSE) -> Suresh Menon | T37: =VLOOKUP(E37,Departments!$A$2:$D$6,4,FALSE) -> 8000000 | U37: =YEAR(G37) -> 2017
A38: E1037 | B38: Aarav | C38: Das | D38: Male | E38: Finance | F38: Finance Manager | G38: 42981 | H38: 91500 | I38: 0 | J38: Poor | K38: Mumbai | L38: Active | M38: 9434999291 | N38: =B38&" "&C38 -> Aarav Das | O38: =SUM(H38:I38) -> 91500 | P38: =DATEDIF(G38,TODAY(),"Y") -> 9 | Q38: =IF(H38>=100000,"A",IF(H38>=60000,"B","C")) -> B | R38: =IF(P38<3,"0-2 yrs",IF(P38<6,"3-5 yrs",IF(P38<9,"6-8 yrs","9+ yrs"))) -> 9+ yrs | S38: =VLOOKUP(E38,Departments!$A$2:$D$6,3,FALSE) -> Suresh Menon | T38: =VLOOKUP(E38,Departments!$A$2:$D$6,4,FALSE) -> 8000000 | U38: =YEAR(G38) -> 2017
A39: E1038 | B39: Meera | C39: Sharma | D39: Female | E39: Finance | F39: Finance Manager | G39: 42733 | H39: 89000 | I39: 0 | J39: Good | K39: Chennai | L39: Active | M39: 9116477768 | N39: =B39&" "&C39 -> Meera Sharma | O39: =SUM(H39:I39) -> 89000 | P39: =DATEDIF(G39,TODAY(),"Y") -> 9 | Q39: =IF(H39>=100000,"A",IF(H39>=60000,"B","C")) -> B | R39: =IF(P39<3,"0-2 yrs",IF(P39<6,"3-5 yrs",IF(P39<9,"6-8 yrs","9+ yrs"))) -> 9+ yrs | S39: =VLOOKUP(E39,Departments!$A$2:$D$6,3,FALSE) -> Suresh Menon | T39: =VLOOKUP(E39,Departments!$A$2:$D$6,4,FALSE) -> 8000000 | U39: =YEAR(G39) -> 2016
A40: E1039 | B40: Sanjay | C40: Brown | D40: Male | E40: HR | F40: HR Manager | G40: 43836 | H40: 51000 | I40: 0 | J40: Average | K40: Delhi | L40: Active | M40: 9686162372 | N40: =B40&" "&C40 -> Sanjay Brown | O40: =SUM(H40:I40) -> 51000 | P40: =DATEDIF(G40,TODAY(),"Y") -> 6 | Q40: =IF(H40>=100000,"A",IF(H40>=60000,"B","C")) -> C | R40: =IF(P40<3,"0-2 yrs",IF(P40<6,"3-5 yrs",IF(P40<9,"6-8 yrs","9+ yrs"))) -> 6-8 yrs | S40: =VLOOKUP(E40,Departments!$A$2:$D$6,3,FALSE) -> Rekha Iyer | T40: =VLOOKUP(E40,Departments!$A$2:$D$6,4,FALSE) -> 5000000 | U40: =YEAR(G40) -> 2020
A41: E1040 | B41: Rohan | C41: Reddy | D41: Male | E41: Marketing | F41: Marketing Analyst | G41: 45414 | H41: 53000 | I41: 0 | J41: Good | K41: Bangalore | L41: Active | M41: No Phone | N41: =B41&" "&C41 -> Rohan Reddy | O41: =SUM(H41:I41) -> 53000 | P41: =DATEDIF(G41,TODAY(),"Y") -> 2 | Q41: =IF(H41>=100000,"A",IF(H41>=60000,"B","C")) -> C | R41: =IF(P41<3,"0-2 yrs",IF(P41<6,"3-5 yrs",IF(P41<9,"6-8 yrs","9+ yrs"))) -> 0-2 yrs | S41: =VLOOKUP(E41,Departments!$A$2:$D$6,3,FALSE) -> David Miller | T41: =VLOOKUP(E41,Departments!$A$2:$D$6,4,FALSE) -> 7000000 | U41: =YEAR(G41) -> 2024
...

Sheet Departments
A1: Department | B1: Location | C1: Department Head | D1: Annual Budget
A2: Engineering | B2: Bangalore | C2: Anil Kumar | D2: 15000000
A3: Sales | B3: Mumbai | C3: Sunita Rao | D3: 9000000
A4: Marketing | B4: Delhi | C4: David Miller | D4: 7000000
A5: HR | B5: Pune | C5: Rekha Iyer | D5: 5000000
A6: Finance | B6: Chennai | C6: Suresh Menon | D6: 8000000

Sheet Report Summary
A1: HR REPORT SUMMARY
A3: Executive summary
A4: The 100-person workforce is mostly active, with 9% recorded attrition. Engineering has the highest average salary and department attrition; HR has the most Poor performance ratings.
A6: Workforce
A7: Total employees | B7: 100
A8: Active | B8: 90
A9: Resigned | B9: 9
A10: On leave | B10: 1
A11: Overall attrition rate | B11: 0.09
A13: Pay (annual salary assumption)
A14: Total salary payroll | B14: 7046500
A15: Average salary | B15: 70465
A16: Highest department average salary | B16: Engineering — 97,563
A17: Lowest department average salary | B17: HR — 57,625
A18: Average salary by gender | B18: Women: 71,222 | Men: 69,576
A20: Performance
A21: Good / Excellent | B21: 40 / 19
A22: Average / Poor | B22: 29 / 12
A23: Most Poor ratings | B23: HR (5), followed by Marketing (4)
A25: Attrition highlights
A26: Highest department attrition | B26: Engineering — 18.8% (3 of 16)
A27: Next highest | B27: Finance — 15.8%; HR — 12.5%
A28: No resignations recorded | B28: Sales and Marketing
A30: Note: Gender salary averages are descriptive only; no adjustment for role, tenure, or other factors.
